Workbook

Sheet PO_AND_PSO
A1: CO-PO Mapping Process
A2: Department of Computer and Communication Engineering
A3: Regulation | B3: R2019 | D3: Course handling Faculty | G3: R.PREETHI
A4: Program | B4: BE-CCE | D4: Course Coordinator | G4: Dr K.Sivakumar
A5: Year / Semester | B5: III/VI | D5: Academic Year | G5: 2024-25
A6: Course Code | B6: R19IT303 | D6: Batch | G6: 2022-26
A7: Course Name | B7: CRYPTOGRAPHY AND CYBERSECURITY | D7: Total Number of Students | G7: 65
A8: Step 1: | B8: The key elements of PO1 to PO12 and PSOs
A9: The program outocmes of a UG program (12 in number)+ 2 PSOs are shown.
A10: PO/PSO | B10: DETAILS | F10: KEY ELEMENTS | I10: NUMBER OF KEY ELEMENTS
A11: 1. Engineering Knowledge | B11: Apply the knowledge of mathematics, science, engineering fundamentals, and an engineering specialization to the solution of complex engineering problems. | F11: 1. Knowledge of maths 2. Sicence fundamentals 3. Engineering fundamentals 4. Engineering knowledge specific to the program | I11: 4
A12: 2. Problem Analysis | B12: Identify, formulate, review research literature, and analyze complex engineering problems reaching substantiated conclusions using first principles of mathematics, natural sciences, and engineering sciences. | F12: 1. Indentify and formulate 2. Review research literature 3. Using first principles of maths 4. Natural sciences 5. Engineering science | I12: 5
A13: 3. Design / Development of solutions | B13: Design solutions for complex engineering problems and design system components or processes that meet the specified needs with appropriate consideration for the public health and safety, and the cultural, societal, and environmental considerations. | F13: 1. Design system components or processes 2. Public health and safety 3. Cultural 4. Societal 5. Environment consideration | I13: 5
A14: 4. Conduct Investigations of complex problems | B14: Use research-based knowledge and research methods including design of experiments, analysis and interpretation of data, and synthesis of the information to provide valid conclusions. | F14: 1. Desgin of experiments 2. Analysis of data 3. Interpretation of data 4. Synthesis of the information | I14: 4
A15: 5. Modern Tool usage | B15: Create, select, and apply appropriate techniques, resources, and modern engineering and IT tools including prediction and modeling to complex engineering activities with an understanding of the limitations. | F15: 1. Create 2. Select and apply appropriate techniques / resources 3. Modern engineering tools 4. IT Tools | I15: 4
A16: 6. The Engineer and Society | B16: Apply reasoning informed by the contextual knowledge to assess societal, health, safety, legal and cultural issues and the consequent responsibilities relevant to the professional engineering practice. | F16: 1. Assess societal issues 2. Assess cultural issues 3. Health and safety issues 4. Legal issues 5. The consequent responsibilities relevant to the professional engineering practices | I16: 5
A17: 7. Environment and Sustainability | B17: Understand the impact of the professional engineering solutions in societal and environmental contexts, and demonstrate the knowledge of, and need for sustainable development. | F17: 1. Impact of the professional engineering solutions in societal context 2. Impact of hte professional engineering solutions in environmental contexts 3. Sustainable development | I17: 3
A18: 8. Ethics | B18: Apply ethical principles and commit to professional ethics and responsibilities and norms of the engineering practice. | F18: 1. Ethical principles 2. Commit to professional ethics. 3. Responsbilities of the engineering practice. 4. Responsibilities and norms of the engineering practice. | I18: 4
A19: 9. Individual and Teamwork | B19: Function effectively as an individual, and as a member or leader in diverse teams, and in multidisciplinary settings. | F19: 1. Funtional individuality 2. Function as a member or leader in diverse teams 3. Function in multidisciplinary settings | I19: 3
A20: 10. Communication | B20: Communicate effectively on complex engineering activities with the engineering community and with society at large, such as, being able to comprehend and write effective reports and design documentation, make effective presentations, and give and receive clear instructions. | F20: 1. Communicate complex engneering activities with the engineering community. 2. Communicate complex engineering activites with society. 3. Comprehend and write effective reports and design documentation. 4. Make effective presentations. 5. Give and receive clear instructions. | I20: 5
A21: 11. Project Management and finance | B21: Demonstrate knowledge and understanding of the engineering and management principles and apply these to one’s own work, as a member and leader in a team, to manage projects and in multidisciplinary environments. | F21: 1. Engineering principles. 2. Mangament principles. 3. Apply to one's own work. 4. Member and leader in a team. 5. Manage projects. 6. Multidisciplinary environments. | I21: 6
A22: 12. Life long learning | B22: Recognize the need for, and have the preparation and ability to engage in independent and life-long learning in the broadest context of technological change. | F22: 1. Engage in independent learning. 2. Life-long learning. 3. Technological change. | I22: 3
... A24: PSO2 | B24: Acquire skills and knowledge to solve real-time challenges in communication networks | F24: 1. Engineering science 2. Science fundamentals. 3. Understanding of problems and finding the optimum solution. 4. Project development. | I24: 4

Sheet CO_PO MAPPING_PRINT
A1: CO-PO/PSO MAPPING
A2: Matrix showning the " the number of key elements of a PO/PSO satisfied by the CO"
A3: CO1 | B3: Apply principles of basic communication systems to design basic modulation schemes for efficient signal transmission.
A4: CO2 | B4: Make use of Symmetric and Asymmetric encryption techniques to solve cryptographic problems.
A5: CO3 | B5: Apply the different cryptographic operations of public key cryptography.
A6: CO4 | B6: Analyze security services in Application, Transport and Network layers.
A7: CO5 | B7: Examine common web application security vulnerabilities and various prevention mechanisms.
A9: Key | B9: 4 | C9: 5 | D9: 5 | E9: 4 | F9: 4 | G9: 5 | H9: 3 | I9: 4 | J9: 3 | K9: 5 | L9: 6 | M9: 3 | N9: =[1]PO_AND_PSO!I24 -> 4 | O9: =[1]PO_AND_PSO!I25 -> 4
A10: CO | B10: Number of key elements of a PO/PSO satisfied by the CO
B11: Program Outcomes (POs) | N11: PSOs
B12: PO1 | C12: PO2 | D12: PO3 | E12: PO4 | F12: PO5 | G12: PO6 | H12: PO7 | I12: PO8 | J12: PO9 | K12: PO10 | L12: PO11 | M12: PO12 | N12: PSO1 | O12: PSO2
A13: CO1-IND | B13: 111 | C13: 1101 | D13: 0 | E13: 0 | F13: 0 | G13: 0 | H13: 0 | I13: 0 | J13: 0 | K13: 0 | L13: 0 | M13: 0 | N13: 0 | O13: 1000
A14: CO1 (Key) | B14: =SUMPRODUCT(1*MID(B13,ROW(INDIRECT("1:"&LEN(B13))),1)) -> 3 | C14: =SUMPRODUCT(1*MID(C13,ROW(INDIRECT("1:"&LEN(C13))),1)) -> 3 | D14: =SUMPRODUCT(1*MID(D13,ROW(INDIRECT("1:"&LEN(D13))),1)) -> 0 | E14: =SUMPRODUCT(1*MID(E13,ROW(INDIRECT("1:"&LEN(E13))),1)) -> 0 | F14: =SUMPRODUCT(1*MID(F13,ROW(INDIRECT("1:"&LEN(F13))),1)) -> 0 | G14: =SUMPRODUCT(1*MID(G13,ROW(INDIRECT("1:"&LEN(G13))),1)) -> 0 | H14: =SUMPRODUCT(1*MID(H13,ROW(INDIRECT("1:"&LEN(H13))),1)) -> 0 | I14: =SUMPRODUCT(1*MID(I13,ROW(INDIRECT("1:"&LEN(I13))),1)) -> 0 | ... O14: =SUMPRODUCT(1*MID(O13,ROW(INDIRECT("1:"&LEN(O13))),1)) -> 1
A15: CO1 (%) | B15: =(B14/B9)*100 -> 75 | C15: =(C14/C9)*100 -> 60 | D15: =(D14/D9)*100 -> 0 | E15: =(E14/E9)*100 -> 0 | F15: =(F14/F9)*100 -> 0 | G15: =(G14/G9)*100 -> 0 | H15: =(H14/H9)*100 -> 0 | I15: =(I14/I9)*100 -> 0 | ... O15: =(O14/O9)*100 -> 25
A16: CO2-IND | B16: 111 | C16: 111 | D16: 110 | E16: 0 | F16: 0 | G16: 0 | H16: 0 | I16: 0 | J16: 0 | K16: 0 | L16: 0 | M16: 0 | N16: 0 | O16: 1000
A17: CO2 (Key) | B17: =SUMPRODUCT(1*MID(B16,ROW(INDIRECT("1:"&LEN(B16))),1)) -> 3 | C17: =SUMPRODUCT(1*MID(C16,ROW(INDIRECT("1:"&LEN(C16))),1)) -> 3 | D17: =SUMPRODUCT(1*MID(D16,ROW(INDIRECT("1:"&LEN(D16))),1)) -> 2 | E17: =SUMPRODUCT(1*MID(E16,ROW(INDIRECT("1:"&LEN(E16))),1)) -> 0 | F17: =SUMPRODUCT(1*MID(F16,ROW(INDIRECT("1:"&LEN(F16))),1)) -> 0 | G17: =SUMPRODUCT(1*MID(G16,ROW(INDIRECT("1:"&LEN(G16))),1)) -> 0 | H17: =SUMPRODUCT(1*MID(H16,ROW(INDIRECT("1:"&LEN(H16))),1)) -> 0 | I17: =SUMPRODUCT(1*MID(I16,ROW(INDIRECT("1:"&LEN(I16))),1)) -> 0 | ... O17: =SUMPRODUCT(1*MID(O16,ROW(INDIRECT("1:"&LEN(O16))),1)) -> 1
A18: CO2 (%) | B18: =(B17/B9)*100 -> 75 | C18: =(C17/C9)*100 -> 60 | D18: =(D17/D9)*100 -> 40 | E18: =(E17/E9)*100 -> 0 | F18: =(F17/F9)*100 -> 0 | G18: =(G17/G9)*100 -> 0 | H18: =(H17/H9)*100 -> 0 | I18: =(I17/I9)*100 -> 0 | ... O18: =(O17/O9)*100 -> 25
A19: CO3 - IND | B19: 111 | C19: 0 | D19: 111 | E19: 0 | F19: 0 | G19: 0 | H19: 0 | I19: 0 | J19: 0 | K19: 0 | L19: 0 | M19: 100 | N19: 0 | O19: 1000
A20: CO3 (Key) | B20: =SUMPRODUCT(1*MID(B19,ROW(INDIRECT("1:"&LEN(B19))),1)) -> 3 | C20: =SUMPRODUCT(1*MID(C19,ROW(INDIRECT("1:"&LEN(C19))),1)) -> 0 | D20: =SUMPRODUCT(1*MID(D19,ROW(INDIRECT("1:"&LEN(D19))),1)) -> 3 | E20: =SUMPRODUCT(1*MID(E19,ROW(INDIRECT("1:"&LEN(E19))),1)) -> 0 | F20: =SUMPRODUCT(1*MID(F19,ROW(INDIRECT("1:"&LEN(F19))),1)) -> 0 | G20: =SUMPRODUCT(1*MID(G19,ROW(INDIRECT("1:"&LEN(G19))),1)) -> 0 | H20: =SUMPRODUCT(1*MID(H19,ROW(INDIRECT("1:"&LEN(H19))),1)) -> 0 | I20: =SUMPRODUCT(1*MID(I19,ROW(INDIRECT("1:"&LEN(I19))),1)) -> 0 | ... O20: =SUMPRODUCT(1*MID(O19,ROW(INDIRECT("1:"&LEN(O19))),1)) -> 1
A21: CO3 (%) | B21: =(B20/B9)*100 -> 75 | C21: =(C20/C9)*100 -> 0 | D21: =(D20/D9)*100 -> 60 | E21: =(E20/E9)*100 -> 0 | F21: =(F20/F9)*100 -> 0 | G21: =(G20/G9)*100 -> 0 | H21: =(H20/H9)*100 -> 0 | I21: =(I20/I9)*100 -> 0 | ... O21: =(O20/O9)*100 -> 25
A22: CO4 -IND | B22: 0 | C22: 1111 | D22: 0 | E22: 1000 | F22: 0 | G22: 0 | H22: 0 | I22: 0 | J22: 0 | K22: 0 | L22: 0 | M22: 100 | N22: 1000 | O22: 0
A23: CO4 (Key) | B23: =SUMPRODUCT(1*MID(B22,ROW(INDIRECT("1:"&LEN(B22))),1)) -> 0 | C23: =SUMPRODUCT(1*MID(C22,ROW(INDIRECT("1:"&LEN(C22))),1)) -> 4 | D23: =SUMPRODUCT(1*MID(D22,ROW(INDIRECT("1:"&LEN(D22))),1)) -> 0 | E23: =SUMPRODUCT(1*MID(E22,ROW(INDIRECT("1:"&LEN(E22))),1)) -> 1 | F23: =SUMPRODUCT(1*MID(F22,ROW(INDIRECT("1:"&LEN(F22))),1)) -> 0 | G23: =SUMPRODUCT(1*MID(G22,ROW(INDIRECT("1:"&LEN(G22))),1)) -> 0 | H23: =SUMPRODUCT(1*MID(H22,ROW(INDIRECT("1:"&LEN(H22))),1)) -> 0 | I23: =SUMPRODUCT(1*MID(I22,ROW(INDIRECT("1:"&LEN(I22))),1)) -> 0 | ... O23: =SUMPRODUCT(1*MID(O22,ROW(INDIRECT("1:"&LEN(O22))),1)) -> 0
A24: CO4 (%) | B24: =(B23/B9)*100 -> 0 | C24: =(C23/C9)*100 -> 80 | D24: =(D23/D9)*100 -> 0 | E24: =(E23/E9)*100 -> 25 | F24: =(F23/F9)*100 -> 0 | G24: =(G23/G9)*100 -> 0 | H24: =(H23/H9)*100 -> 0 | I24: =(I23/I9)*100 -> 0 | ... O24: =(O23/O9)*100 -> 0
A25: CO5 -IND | B25: 0 | C25: 1111 | D25: 1010 | E25: 1 | F25: 0 | G25: 0 | H25: 0 | I25: 0 | J25: 0 | K25: 0 | L25: 0 | M25: 100 | N25: 1000 | O25: 0
A26: CO5 (Key) | B26: =SUMPRODUCT(1*MID(B25,ROW(INDIRECT("1:"&LEN(B25))),1)) -> 0 | C26: =SUMPRODUCT(1*MID(C25,ROW(INDIRECT("1:"&LEN(C25))),1)) -> 4 | D26: =SUMPRODUCT(1*MID(D25,ROW(INDIRECT("1:"&LEN(D25))),1)) -> 2 | E26: =SUMPRODUCT(1*MID(E25,ROW(INDIRECT("1:"&LEN(E25))),1)) -> 1 | F26: =SUMPRODUCT(1*MID(F25,ROW(INDIRECT("1:"&LEN(F25))),1)) -> 0 | G26: =SUMPRODUCT(1*MID(G25,ROW(INDIRECT("1:"&LEN(G25))),1)) -> 0 | H26: =SUMPRODUCT(1*MID(H25,ROW(INDIRECT("1:"&LEN(H25))),1)) -> 0 | I26: =SUMPRODUCT(1*MID(I25,ROW(INDIRECT("1:"&LEN(I25))),1)) -> 0 | ... O26: =SUMPRODUCT(1*MID(O25,ROW(INDIRECT("1:"&LEN(O25))),1)) -> 0
A27: CO5 (%) | B27: =(B26/B9)*100 -> 0 | C27: =(C26/C9)*100 -> 80 | D27: =(D26/D9)*100 -> 40 | E27: =(E26/E9)*100 -> 25 | F27: =(F26/F9)*100 -> 0 | G27: =(G26/G9)*100 -> 0 | H27: =(H26/H9)*100 -> 0 | I27: =(I26/I9)*100 -> 0 | ... O27: =(O26/O9)*100 -> 0
A29: The final CO-PO/PSO correlation matrix based on weightage taken as a grade.
A30: when the value of "C" (contribution percentage) is | D30: Strength of correlation | G30: Grade to indicate the strength of correlation of CO with PO/PSO
G31: Grade in numerals | K31: Grade as an alphabet
A32: < 25 % | D32: No correlation | G32: - | K32: -
A33: >= 25% to < 50% | D33: Weak correlation | G33: 1 | K33: W
A34: >= 50% to < 75% | D34: Medium correlation | G34: 2 | K34: M
A35: >= 75% | D35: Strong correlation | G35: 3 | K35: S
A37: FINAL CO-PO/PSO MAPPING
A38: Course Articulation Matrix
A39: CO/PO&PSO Mappings (S/M/W indicates strength of correlation) S - (3) Strong, M (2) - Medium, W (1) - Weak
A40: CO | B40: Program Outcomes (PO) | N40: PSOs
B41: PO1 | C41: PO2 | D41: PO3 | E41: PO4 | F41: PO5 | G41: PO6 | H41: PO7 | I41: PO8 | J41: PO9 | K41: PO10 | L41: PO11 | M41: PO12 | N41: PSO1 | O41: PSO2
A42: CO1 | B42: =IF(B15<25,"-",IF(AND(B15>=25,B15<50),"1",IF(AND(B15>=50,B15<75),"2",IF(B15>=75,"3")))) -> 3 | C42: =IF(C15<25,"-",IF(AND(C15>=25,C15<50),"1",IF(AND(C15>=50,C15<75),"2",IF(C15>=75,"3")))) -> 2 | D42: =IF(D15<25,"-",IF(AND(D15>=25,D15<50),"1",IF(AND(D15>=50,D15<75),"2",IF(D15>=75,"3")))) -> - | E42: =IF(E15<25,"-",IF(AND(E15>=25,E15<50),"1",IF(AND(E15>=50,E15<75),"2",IF(E15>=75,"3")))) -> - | F42: =IF(F15<25,"-",IF(AND(F15>=25,F15<50),"1",IF(AND(F15>=50,F15<75),"2",IF(F15>=75,"3")))) -> - | G42: =IF(G15<25,"-",IF(AND(G15>=25,G15<50),"1",IF(AND(G15>=50,G15<75),"2",IF(G15>=75,"3")))) -> - | H42: =IF(H15<25,"-",IF(AND(H15>=25,H15<50),"1",IF(AND(H15>=50,H15<75),"2",IF(H15>=75,"3")))) -> - | I42: =IF(I15<25,"-",IF(AND(I15>=25,I15<50),"1",IF(AND(I15>=50,I15<75),"2",IF(I15>=75,"3")))) -> - | ... O42: =IF(O15<25,"-",IF(AND(O15>=25,O15<50),"1",IF(AND(O15>=50,O15<75),"2",IF(O15>=75,"3")))) -> 1
A43: CO2 | B43: =IF(B18<25,"-",IF(AND(B18>=25,B18<50),"1",IF(AND(B18>=50,B18<75),"2",IF(B18>=75,"3")))) -> 3 | C43: =IF(C18<25,"-",IF(AND(C18>=25,C18<50),"1",IF(AND(C18>=50,C18<75),"2",IF(C18>=75,"3")))) -> 2 | D43: =IF(D18<25,"-",IF(AND(D18>=25,D18<50),"1",IF(AND(D18>=50,D18<75),"2",IF(D18>=75,"3")))) -> 1 | E43: =IF(E18<25,"-",IF(AND(E18>=25,E18<50),"1",IF(AND(E18>=50,E18<75),"2",IF(E18>=75,"3")))) -> - | F43: =IF(F18<25,"-",IF(AND(F18>=25,F18<50),"1",IF(AND(F18>=50,F18<75),"2",IF(F18>=75,"3")))) -> - | G43: =IF(G18<25,"-",IF(AND(G18>=25,G18<50),"1",IF(AND(G18>=50,G18<75),"2",IF(G18>=75,"3")))) -> - | H43: =IF(H18<25,"-",IF(AND(H18>=25,H18<50),"1",IF(AND(H18>=50,H18<75),"2",IF(H18>=75,"3")))) -> - | I43: =IF(I18<25,"-",IF(AND(I18>=25,I18<50),"1",IF(AND(I18>=50,I18<75),"2",IF(I18>=75,"3")))) -> - | ... O43: =IF(O18<25,"-",IF(AND(O18>=25,O18<50),"1",IF(AND(O18>=50,O18<75),"2",IF(O18>=75,"3")))) -> 1
...

Sheet CO_ATT_INPUTS
A1: Sri Eshwar College of Engineering
A2: Coimbatore - 641 202
A3: =PO_AND_PSO!A2 -> Department of Computer and Communication Engineering
A5: =[2]PO_AND_PSO!A3 -> Regulation | D5: =PO_AND_PSO!B3 -> R2019
A6: =[2]PO_AND_PSO!A4 -> Program | D6: =PO_AND_PSO!B4 -> BE-CCE
A7: =[2]PO_AND_PSO!A5 -> Year/Semester | D7: =PO_AND_PSO!B5 -> III/VI
A8: =[2]PO_AND_PSO!A6 -> Course Code | D8: =PO_AND_PSO!B6 -> R19IT303
A9: =[2]PO_AND_PSO!A7 -> Course Name | D9: =PO_AND_PSO!B7 -> CRYPTOGRAPHY AND CYBERSECURITY
A10: =[2]PO_AND_PSO!D3 -> Course handling Faculty | D10: =PO_AND_PSO!G3 -> R.PREETHI
A11: =[2]PO_AND_PSO!D4 -> Course Coordinator | D11: =PO_AND_PSO!G4 -> Dr K.Sivakumar
A12: =[2]PO_AND_PSO!D5 -> Academic Year | D12: =PO_AND_PSO!G5 -> 2024-25
A13: =[2]PO_AND_PSO!D6 -> Batch | D13: =PO_AND_PSO!G6 -> 2022-26
A14: =[2]PO_AND_PSO!D7 -> Total Number of Students | D14: =PO_AND_PSO!G7 -> 65
A16: S. No | B16: ROLL NUM | C16: REGISTER NUMBER | D16: NAME OF THE STUDENT | E16: CIA | J16: Assignment | O16: Presentation / Tutorial | P16: Quiz | Q16: End Semester Marks | V16: CIA+ASSIGNMENT+PRESENTATION/ TUTORIAL+ QUIZ (X) X = (Total marks scored in particular CO / Total Denominator)*100 | AA16: END SEMESTER MARKS (%) (Y) | AF16: DIRECT ATTAINMENT (0.4X + 0.6Y)
E17: CO1 | F17: CO2 | G17: CO3 | H17: CO4 | I17: CO5 | J17: CO1 | K17: CO2 | L17: CO3 | M17: CO4 | N17: CO5 | Q17: CO1 | R17: CO2 | S17: CO3 | T17: CO4 | U17: CO5
E18: 40 | F18: 40 | G18: 40 | H18: 40 | I18: 40 | J18: 10 | K18: 10 | L18: 10 | M18: 10 | N18: 10 | O18: 100 | P18: 100 | Q18: 20 | R18: 20 | S18: 20 | T18: 20 | U18: 20 | V18: CO1 | W18: CO2 | X18: CO3 | Y18: CO4 | Z18: CO5 | AA18: CO1 | AB18: CO2 | AC18: CO3 | AD18: CO4 | AE18: CO5 | AF18: CO1 | AG18: CO2 | AH18: CO3 | AI18: CO4 | AJ18: CO5
A19: 1 | B19: 22CC001 | C19: 722822115001 | D19: AFREED S | E19: 26 | F19: 26 | G19: 23 | H19: 32 | I19: 31 | J19: 9 | K19: 9 | L19: 9 | M19: 9 | N19: 9 | O19: 90 | P19: 100 | Q19: 17 | R19: 14 | S19: 20 | T19: 14 | U19: 12 | V19: =((((E19*2.5)+(J19*10)+O19+P19)/(400))*100) -> 86.25 | W19: =((((F19*2.5)+(K19*10)+O19+P19)/(400))*100) -> 86.25 | X19: =((((G19*2.5)+(L19*10)+O19+P19)/(400))*100) -> 84.375 | Y19: =((((H19*2.5)+(M19*10)+O19+P19)/(400))*100) -> 90 | Z19: =((((I19*2.5)+(N19*10)+O19+P19)/(400))*100) -> 89.375 | AA19: =(Q19/20)*100 -> 85 | AB19: =(R19/20)*100 -> 70 | AC19: =(S19/20)*100 -> 100 | AD19: =(T19/20)*100 -> 70 | AE19: =(U19/20)*100 -> 60 | AF19: =(V19*0.4+AA19*0.6) -> 85.5 | AG19: =(W19*0.4+AB19*0.6) -> 76.5 | AH19: =(X19*0.4+AC19*0.6) -> 93.75 | AI19: =(Y19*0.4+AD19*0.6) -> 78 | AJ19: =(Z19*0.4+AE19*0.6) -> 71.75
A20: 2 | B20: 22CC002 | C20: 722822115002 | D20: AJAY J | E20: 19 | F20: 30 | G20: 27 | H20: 28 | I20: 21 | J20: 8 | K20: 8 | L20: 8 | M20: 8 | N20: 8 | O20: 92 | P20: 98 | Q20: 13 | R20: 13 | S20: 13 | T20: 10 | U20: 12 | V20: =((((E20*2.5)+(J20*10)+O20+P20)/(400))*100) -> 79.375 | W20: =((((F20*2.5)+(K20*10)+O20+P20)/(400))*100) -> 86.25 | X20: =((((G20*2.5)+(L20*10)+O20+P20)/(400))*100) -> 84.375 | Y20: =((((H20*2.5)+(M20*10)+O20+P20)/(400))*100) -> 85 | Z20: =((((I20*2.5)+(N20*10)+O20+P20)/(400))*100) -> 80.625 | AA20: =(Q20/20)*100 -> 65 | AB20: =(R20/20)*100 -> 65 | AC20: =(S20/20)*100 -> 65 | AD20: =(T20/20)*100 -> 50 | AE20: =(U20/20)*100 -> 60 | AF20: =(V20*0.4+AA20*0.6) -> 70.75 | AG20: =(W20*0.4+AB20*0.6) -> 73.5 | AH20: =(X20*0.4+AC20*0.6) -> 72.75 | AI20: =(Y20*0.4+AD20*0.6) -> 64 | AJ20: =(Z20*0.4+AE20*0.6) -> 68.25
A21: 3 | B21: 22CC003 | C21: 722822115003 | D21: AKSHAYAN K | E21: 33 | F21: 18 | G21: 23 | H21: 26 | I21: 21 | J21: 9 | K21: 9 | L21: 9 | M21: 9 | N21: 9 | O21: 90 | P21: 100 | Q21: 13 | R21: 13 | S21: 12 | T21: 12 | U21: 11 | V21: =((((E21*2.5)+(J21*10)+O21+P21)/(400))*100) -> 90.625 | W21: =((((F21*2.5)+(K21*10)+O21+P21)/(400))*100) -> 81.25 | X21: =((((G21*2.5)+(L21*10)+O21+P21)/(400))*100) -> 84.375 | Y21: =((((H21*2.5)+(M21*10)+O21+P21)/(400))*100) -> 86.25 | Z21: =((((I21*2.5)+(N21*10)+O21+P21)/(400))*100) -> 83.125 | AA21: =(Q21/20)*100 -> 65 | AB21: =(R21/20)*100 -> 65 | AC21: =(S21/20)*100 -> 60 | AD21: =(T21/20)*100 -> 60 | AE21: =(U21/20)*100 -> 55 | AF21: =(V21*0.4+AA21*0.6) -> 75.25 | AG21: =(W21*0.4+AB21*0.6) -> 71.5 | AH21: =(X21*0.4+AC21*0.6) -> 69.75 | AI21: =(Y21*0.4+AD21*0.6) -> 70.5 | AJ21: =(Z21*0.4+AE21*0.6) -> 66.25
A22: 4 | B22: 22CC004 | C22: 722822115004 | D22: DARSHAN R B | E22: 25 | F22: 22 | G22: 23 | H22: 23 | I22: 14 | J22: 9 | K22: 9 | L22: 9 | M22: 9 | N22: 9 | O22: 90 | P22: 100 | Q22: 13 | R22: 11 | S22: 11 | T22: 11 | U22: 12 | V22: =((((E22*2.5)+(J22*10)+O22+P22)/(400))*100) -> 85.625 | W22: =((((F22*2.5)+(K22*10)+O22+P22)/(400))*100) -> 83.75 | X22: =((((G22*2.5)+(L22*10)+O22+P22)/(400))*100) -> 84.375 | Y22: =((((H22*2.5)+(M22*10)+O22+P22)/(400))*100) -> 84.375 | Z22: =((((I22*2.5)+(N22*10)+O22+P22)/(400))*100) -> 78.75 | AA22: =(Q22/20)*100 -> 65 | AB22: =(R22/20)*100 -> 55 | AC22: =(S22/20)*100 -> 55 | AD22: =(T22/20)*100 -> 55 | AE22: =(U22/20)*100 -> 60 | AF22: =(V22*0.4+AA22*0.6) -> 73.25 | AG22: =(W22*0.4+AB22*0.6) -> 66.5 | AH22: =(X22*0.4+AC22*0.6) -> 66.75 | AI22: =(Y22*0.4+AD22*0.6) -> 66.75 | AJ22: =(Z22*0.4+AE22*0.6) -> 67.5
A23: 5 | B23: 22CC005 | C23: 722822115005 | D23: DEEPAK RAJA M | E23: 26 | F23: 23 | G23: 31 | H23: 36 | I23: 33 | J23: 9 | K23: 9 | L23: 9 | M23: 9 | N23: 9 | O23: 90 | P23: 100 | Q23: 16 | R23: 15 | S23: 15 | T23: 16 | U23: 13 | V23: =((((E23*2.5)+(J23*10)+O23+P23)/(400))*100) -> 86.25 | W23: =((((F23*2.5)+(K23*10)+O23+P23)/(400))*100) -> 84.375 | X23: =((((G23*2.5)+(L23*10)+O23+P23)/(400))*100) -> 89.375 | Y23: =((((H23*2.5)+(M23*10)+O23+P23)/(400))*100) -> 92.5 | Z23: =((((I23*2.5)+(N23*10)+O23+P23)/(400))*100) -> 90.625 | AA23: =(Q23/20)*100 -> 80 | AB23: =(R23/20)*100 -> 75 | AC23: =(S23/20)*100 -> 75 | AD23: =(T23/20)*100 -> 80 | AE23: =(U23/20)*100 -> 65 | AF23: =(V23*0.4+AA23*0.6) -> 82.5 | AG23: =(W23*0.4+AB23*0.6) -> 78.75 | AH23: =(X23*0.4+AC23*0.6) -> 80.75 | AI23: =(Y23*0.4+AD23*0.6) -> 85 | AJ23: =(Z23*0.4+AE23*0.6) -> 75.25
A24: 6 | B24: 22CC006 | C24: 722822115006 | D24: DHANUSHPRIYAN S | E24: 34 | F24: 25 | G24: 21 | H24: 33 | I24: 30 | J24: 9 | K24: 9 | L24: 9 | M24: 9 | N24: 9 | O24: 92 | P24: 100 | Q24: 17 | R24: 15 | S24: 14 | T24: 13 | U24: 12 | V24: =((((E24*2.5)+(J24*10)+O24+P24)/(400))*100) -> 91.75 | W24: =((((F24*2.5)+(K24*10)+O24+P24)/(400))*100) -> 86.125 | X24: =((((G24*2.5)+(L24*10)+O24+P24)/(400))*100) -> 83.625 | Y24: =((((H24*2.5)+(M24*10)+O24+P24)/(400))*100) -> 91.125 | Z24: =((((I24*2.5)+(N24*10)+O24+P24)/(400))*100) -> 89.25 | AA24: =(Q24/20)*100 -> 85 | AB24: =(R24/20)*100 -> 75 | AC24: =(S24/20)*100 -> 70 | AD24: =(T24/20)*100 -> 65 | AE24: =(U24/20)*100 -> 60 | AF24: =(V24*0.4+AA24*0.6) -> 87.7 | AG24: =(W24*0.4+AB24*0.6) -> 79.45 | AH24: =(X24*0.4+AC24*0.6) -> 75.45 | AI24: =(Y24*0.4+AD24*0.6) -> 75.45 | AJ24: =(Z24*0.4+AE24*0.6) -> 71.7
A25: 7 | B25: 22CC007 | C25: 722822115007 | D25: DHARSHINI K | E25: 31 | F25: 27 | G25: 28 | H25: 35 | I25: 29 | J25: 9 | K25: 9 | L25: 9 | M25: 9 | N25: 9 | O25: 96 | P25: 93 | Q25: 18 | R25: 18 | S25: 16 | T25: 15 | U25: 14 | V25: =((((E25*2.5)+(J25*10)+O25+P25)/(400))*100) -> 89.125 | W25: =((((F25*2.5)+(K25*10)+O25+P25)/(400))*100) -> 86.625 | X25: =((((G25*2.5)+(L25*10)+O25+P25)/(400))*100) -> 87.25 | Y25: =((((H25*2.5)+(M25*10)+O25+P25)/(400))*100) -> 91.625 | Z25: =((((I25*2.5)+(N25*10)+O25+P25)/(400))*100) -> 87.875 | AA25: =(Q25/20)*100 -> 90 | AB25: =(R25/20)*100 -> 90 | AC25: =(S25/20)*100 -> 80 | AD25: =(T25/20)*100 -> 75 | AE25: =(U25/20)*100 -> 70 | AF25: =(V25*0.4+AA25*0.6) -> 89.65 | AG25: =(W25*0.4+AB25*0.6) -> 88.65 | AH25: =(X25*0.4+AC25*0.6) -> 82.9 | AI25: =(Y25*0.4+AD25*0.6) -> 81.65 | AJ25: =(Z25*0.4+AE25*0.6) -> 77.15
A26: 8 | B26: 22CC008 | C26: 722822115008 | D26: DHEVADHARSHINI M | E26: 33 | F26: 31 | G26: 35 | H26: 36 | I26: 29 | J26: 9 | K26: 9 | L26: 9 | M26: 9 | N26: 9 | O26: 96 | P26: 100 | Q26: 17 | R26: 16 | S26: 16 | T26: 13 | U26: 14 | V26: =((((E26*2.5)+(J26*10)+O26+P26)/(400))*100) -> 92.125 | W26: =((((F26*2.5)+(K26*10)+O26+P26)/(400))*100) -> 90.875 | X26: =((((G26*2.5)+(L26*10)+O26+P26)/(400))*100) -> 93.375 | Y26: =((((H26*2.5)+(M26*10)+O26+P26)/(400))*100) -> 94 | Z26: =((((I26*2.5)+(N26*10)+O26+P26)/(400))*100) -> 89.625 | AA26: =(Q26/20)*100 -> 85 | AB26: =(R26/20)*100 -> 80 | AC26: =(S26/20)*100 -> 80 | AD26: =(T26/20)*100 -> 65 | AE26: =(U26/20)*100 -> 70 | AF26: =(V26*0.4+AA26*0.6) -> 87.85 | AG26: =(W26*0.4+AB26*0.6) -> 84.35 | AH26: =(X26*0.4+AC26*0.6) -> 85.35 | AI26: =(Y26*0.4+AD26*0.6) -> 76.6 | AJ26: =(Z26*0.4+AE26*0.6) -> 77.85
A27: 9 | B27: 22CC009 | C27: 722822115009 | D27: DINESH R | E27: 27 | F27: 27 | G27: 22 | H27: 33 | I27: 30 | J27: 9 | K27: 9 | L27: 9 | M27: 9 | N27: 9 | O27: 94 | P27: 100 | Q27: 12 | R27: 12 | S27: 12 | T27: 10 | U27: 12 | V27: =((((E27*2.5)+(J27*10)+O27+P27)/(400))*100) -> 87.875 | W27: =((((F27*2.5)+(K27*10)+O27+P27)/(400))*100) -> 87.875 | X27: =((((G27*2.5)+(L27*10)+O27+P27)/(400))*100) -> 84.75 | Y27: =((((H27*2.5)+(M27*10)+O27+P27)/(400))*100) -> 91.625 | Z27: =((((I27*2.5)+(N27*10)+O27+P27)/(400))*100) -> 89.75 | AA27: =(Q27/20)*100 -> 60 | AB27: =(R27/20)*100 -> 60 | AC27: =(S27/20)*100 -> 60 | AD27: =(T27/20)*100 -> 50 | AE27: =(U27/20)*100 -> 60 | AF27: =(V27*0.4+AA27*0.6) -> 71.15 | AG27: =(W27*0.4+AB27*0.6) -> 71.15 | AH27: =(X27*0.4+AC27*0.6) -> 69.9 | AI27: =(Y27*0.4+AD27*0.6) -> 66.65 | AJ27: =(Z27*0.4+AE27*0.6) -> 71.9
A28: 10 | B28: 22CC010 | C28: 722822115010 | D28: ELANGO T | E28: 31 | F28: 27 | G28: 28 | H28: 33 | I28: 31 | J28: 9 | K28: 9 | L28: 9 | M28: 9 | N28: 9 | O28: 92 | P28: 100 | Q28: 17 | R28: 18 | S28: 16 | T28: 17 | U28: 17 | V28: =((((E28*2.5)+(J28*10)+O28+P28)/(400))*100) -> 89.875 | W28: =((((F28*2.5)+(K28*10)+O28+P28)/(400))*100) -> 87.375 | X28: =((((G28*2.5)+(L28*10)+O28+P28)/(400))*100) -> 88 | Y28: =((((H28*2.5)+(M28*10)+O28+P28)/(400))*100) -> 91.125 | Z28: =((((I28*2.5)+(N28*10)+O28+P28)/(400))*100) -> 89.875 | AA28: =(Q28/20)*100 -> 85 | AB28: =(R28/20)*100 -> 90 | AC28: =(S28/20)*100 -> 80 | AD28: =(T28/20)*100 -> 85 | AE28: =(U28/20)*100 -> 85 | AF28: =(V28*0.4+AA28*0.6) -> 86.95 | AG28: =(W28*0.4+AB28*0.6) -> 88.95 | AH28: =(X28*0.4+AC28*0.6) -> 83.2 | AI28: =(Y28*0.4+AD28*0.6) -> 87.45 | AJ28: =(Z28*0.4+AE28*0.6) -> 86.95
A29: 11 | B29: 22CC011 | C29: 722822115011 | D29: GAYATHIRI K | E29: 20 | F29: 31 | G29: 27 | H29: 33 | I29: 32 | J29: 9 | K29: 9 | L29: 9 | M29: 9 | N29: 9 | O29: 90 | P29: 100 | Q29: 17 | R29: 16 | S29: 16 | T29: 16 | U29: 16 | V29: =((((E29*2.5)+(J29*10)+O29+P29)/(400))*100) -> 82.5 | W29: =((((F29*2.5)+(K29*10)+O29+P29)/(400))*100) -> 89.375 | X29: =((((G29*2.5)+(L29*10)+O29+P29)/(400))*100) -> 86.875 | Y29: =((((H29*2.5)+(M29*10)+O29+P29)/(400))*100) -> 90.625 | Z29: =((((I29*2.5)+(N29*10)+O29+P29)/(400))*100) -> 90 | AA29: =(Q29/20)*100 -> 85 | AB29: =(R29/20)*100 -> 80 | AC29: =(S29/20)*100 -> 80 | AD29: =(T29/20)*100 -> 80 | AE29: =(U29/20)*100 -> 80 | AF29: =(V29*0.4+AA29*0.6) -> 84 | AG29: =(W29*0.4+AB29*0.6) -> 83.75 | AH29: =(X29*0.4+AC29*0.6) -> 82.75 | AI29: =(Y29*0.4+AD29*0.6) -> 84.25 | AJ29: =(Z29*0.4+AE29*0.6) -> 84
A30: 12 | B30: 22CC012 | C30: 722822115012 | D30: GNANARIDDHIKA R | E30: 31 | F30: 18 | G30: 26 | H30: 30 | I30: 31 | J30: 8 | K30: 8 | L30: 8 | M30: 8 | N30: 8 | O30: 96 | P30: 100 | Q30: 16 | R30: 12 | S30: 14 | T30: 16 | U30: 13 | V30: =((((E30*2.5)+(J30*10)+O30+P30)/(400))*100) -> 88.375 | W30: =((((F30*2.5)+(K30*10)+O30+P30)/(400))*100) -> 80.25 | X30: =((((G30*2.5)+(L30*10)+O30+P30)/(400))*100) -> 85.25 | Y30: =((((H30*2.5)+(M30*10)+O30+P30)/(400))*100) -> 87.75 | Z30: =((((I30*2.5)+(N30*10)+O30+P30)/(400))*100) -> 88.375 | AA30: =(Q30/20)*100 -> 80 | AB30: =(R30/20)*100 -> 60 | AC30: =(S30/20)*100 -> 70 | AD30: =(T30/20)*100 -> 80 | AE30: =(U30/20)*100 -> 65 | AF30: =(V30*0.4+AA30*0.6) -> 83.35 | AG30: =(W30*0.4+AB30*0.6) -> 68.1 | AH30: =(X30*0.4+AC30*0.6) -> 76.1 | AI30: =(Y30*0.4+AD30*0.6) -> 83.1 | AJ30: =(Z30*0.4+AE30*0.6) -> 74.35
... A83: 65 | B83: 22CC302 | C83: 722822115302 | D83: RAKESH M | E83: 16 | F83: 8 | G83: 22 | H83: 32 | I83: 29 | J83: 8 | K83: 8 | L83: 8 | M83: 8 | N83: 8 | O83: 92 | P83: 90 | Q83: 18 | R83: 16 | S83: 16 | T83: 16 | U83: 16 | V83: =((((E83*2.5)+(J83*10)+O83+P83)/(400))*100) -> 75.5 | W83: =((((F83*2.5)+(K83*10)+O83+P83)/(400))*100) -> 70.5 | X83: =((((G83*2.5)+(L83*10)+O83+P83)/(400))*100) -> 79.25 | Y83: =((((H83*2.5)+(M83*10)+O83+P83)/(400))*100) -> 85.5 | Z83: =((((I83*2.5)+(N83*10)+O83+P83)/(400))*100) -> 83.625 | AA83: =(Q83/20)*100 -> 90 | AB83: =(R83/20)*100 -> 80 | AC83: =(S83/20)*100 -> 80 | AD83: =(T83/20)*100 -> 80 | AE83: =(U83/20)*100 -> 80 | AF83: =(V83*0.4+AA83*0.6) -> 84.2 | AG83: =(W83*0.4+AB83*0.6) -> 76.2 | AH83: =(X83*0.4+AC83*0.6) -> 79.7 | AI83: =(Y83*0.4+AD83*0.6) -> 82.2 | AJ83: =(Z83*0.4+AE83*0.6) -> 81.45
A84: 66 | V84: =((((E84*2.5)+(J84*10)+O84+P84)/(400))*100) -> 0 | W84: =((((F84*2.5)+(K84*10)+O84+P84)/(400))*100) -> 0 | X84: =((((G84*2.5)+(L84*10)+O84+P84)/(400))*100) -> 0 | Y84: =((((H84*2.5)+(M84*10)+O84+P84)/(400))*100) -> 0 | Z84: =((((I84*2.5)+(N84*10)+O84+P84)/(400))*100) -> 0 | AA84: =(Q84/20)*100 -> 0 | AB84: =(R84/20)*100 -> 0 | AC84: =(S84/20)*100 -> 0 | AD84: =(T84/20)*100 -> 0 | AE84: =(U84/20)*100 -> 0 | AF84: =(V84*0.4+AA84*0.6) -> 0 | AG84: =(W84*0.4+AB84*0.6) -> 0 | AH84: =(X84*0.4+AC84*0.6) -> 0 | AI84: =(Y84*0.4+AD84*0.6) -> 0 | AJ84: =(Z84*0.4+AE84*0.6) -> 0
A85: 67 | V85: =((((E85*2.5)+(J85*10)+O85+P85)/(400))*100) -> 0 | W85: =((((F85*2.5)+(K85*10)+O85+P85)/(400))*100) -> 0 | X85: =((((G85*2.5)+(L85*10)+O85+P85)/(400))*100) -> 0 | Y85: =((((H85*2.5)+(M85*10)+O85+P85)/(400))*100) -> 0 | Z85: =((((I85*2.5)+(N85*10)+O85+P85)/(400))*100) -> 0 | AA85: =(Q85/20)*100 -> 0 | AB85: =(R85/20)*100 -> 0 | AC85: =(S85/20)*100 -> 0 | AD85: =(T85/20)*100 -> 0 | AE85: =(U85/20)*100 -> 0 | AF85: =(V85*0.4+AA85*0.6) -> 0 | AG85: =(W85*0.4+AB85*0.6) -> 0 | AH85: =(X85*0.4+AC85*0.6) -> 0 | AI85: =(Y85*0.4+AD85*0.6) -> 0 | AJ85: =(Z85*0.4+AE85*0.6) -> 0
A86: 68 | V86: =((((E86*2.5)+(J86*10)+O86+P86)/(400))*100) -> 0 | W86: =((((F86*2.5)+(K86*10)+O86+P86)/(400))*100) -> 0 | X86: =((((G86*2.5)+(L86*10)+O86+P86)/(400))*100) -> 0 | Y86: =((((H86*2.5)+(M86*10)+O86+P86)/(400))*100) -> 0 | Z86: =((((I86*2.5)+(N86*10)+O86+P86)/(400))*100) -> 0 | AA86: =(Q86/20)*100 -> 0 | AB86: =(R86/20)*100 -> 0 | AC86: =(S86/20)*100 -> 0 | AD86: =(T86/20)*100 -> 0 | AE86: =(U86/20)*100 -> 0 | AF86: =(V86*0.4+AA86*0.6) -> 0 | AG86: =(W86*0.4+AB86*0.6) -> 0 | AH86: =(X86*0.4+AC86*0.6) -> 0 | AI86: =(Y86*0.4+AD86*0.6) -> 0 | AJ86: =(Z86*0.4+AE86*0.6) -> 0
A87: 69 | V87: =((((E87*2.5)+(J87*10)+O87+P87)/(400))*100) -> 0 | W87: =((((F87*2.5)+(K87*10)+O87+P87)/(400))*100) -> 0 | X87: =((((G87*2.5)+(L87*10)+O87+P87)/(400))*100) -> 0 | Y87: =((((H87*2.5)+(M87*10)+O87+P87)/(400))*100) -> 0 | Z87: =((((I87*2.5)+(N87*10)+O87+P87)/(400))*100) -> 0 | AA87: =(Q87/20)*100 -> 0 | AB87: =(R87/20)*100 -> 0 | AC87: =(S87/20)*100 -> 0 | AD87: =(T87/20)*100 -> 0 | AE87: =(U87/20)*100 -> 0 | AF87: =(V87*0.4+AA87*0.6) -> 0 | AG87: =(W87*0.4+AB87*0.6) -> 0 | AH87: =(X87*0.4+AC87*0.6) -> 0 | AI87: =(Y87*0.4+AD87*0.6) -> 0 | AJ87: =(Z87*0.4+AE87*0.6) -> 0
A88: 70 | V88: =((((E88*2.5)+(J88*10)+O88+P88)/(400))*100) -> 0 | W88: =((((F88*2.5)+(K88*10)+O88+P88)/(400))*100) -> 0 | X88: =((((G88*2.5)+(L88*10)+O88+P88)/(400))*100) -> 0 | Y88: =((((H88*2.5)+(M88*10)+O88+P88)/(400))*100) -> 0 | Z88: =((((I88*2.5)+(N88*10)+O88+P88)/(400))*100) -> 0 | AA88: =(Q88/20)*100 -> 0 | AB88: =(R88/20)*100 -> 0 | AC88: =(S88/20)*100 -> 0 | AD88: =(T88/20)*100 -> 0 | AE88: =(U88/20)*100 -> 0 | AF88: =(V88*0.4+AA88*0.6) -> 0 | AG88: =(W88*0.4+AB88*0.6) -> 0 | AH88: =(X88*0.4+AC88*0.6) -> 0 | AI88: =(Y88*0.4+AD88*0.6) -> 0 | AJ88: =(Z88*0.4+AE88*0.6) -> 0
A89: 71 | V89: =((((E89*2.5)+(J89*10)+O89+P89)/(400))*100) -> 0 | W89: =((((F89*2.5)+(K89*10)+O89+P89)/(400))*100) -> 0 | X89: =((((G89*2.5)+(L89*10)+O89+P89)/(400))*100) -> 0 | Y89: =((((H89*2.5)+(M89*10)+O89+P89)/(400))*100) -> 0 | Z89: =((((I89*2.5)+(N89*10)+O89+P89)/(400))*100) -> 0 | AA89: =(Q89/20)*100 -> 0 | AB89: =(R89/20)*100 -> 0 | AC89: =(S89/20)*100 -> 0 | AD89: =(T89/20)*100 -> 0 | AE89: =(U89/20)*100 -> 0 | AF89: =(V89*0.4+AA89*0.6) -> 0 | AG89: =(W89*0.4+AB89*0.6) -> 0 | AH89: =(X89*0.4+AC89*0.6) -> 0 | AI89: =(Y89*0.4+AD89*0.6) -> 0 | AJ89: =(Z89*0.4+AE89*0.6) -> 0
A90: 72 | V90: =((((E90*2.5)+(J90*10)+O90+P90)/(400))*100) -> 0 | W90: =((((F90*2.5)+(K90*10)+O90+P90)/(400))*100) -> 0 | X90: =((((G90*2.5)+(L90*10)+O90+P90)/(400))*100) -> 0 | Y90: =((((H90*2.5)+(M90*10)+O90+P90)/(400))*100) -> 0 | Z90: =((((I90*2.5)+(N90*10)+O90+P90)/(400))*100) -> 0 | AA90: =(Q90/20)*100 -> 0 | AB90: =(R90/20)*100 -> 0 | AC90: =(S90/20)*100 -> 0 | AD90: =(T90/20)*100 -> 0 | AE90: =(U90/20)*100 -> 0 | AF90: =(V90*0.4+AA90*0.6) -> 0 | AG90: =(W90*0.4+AB90*0.6) -> 0 | AH90: =(X90*0.4+AC90*0.6) -> 0 | AI90: =(Y90*0.4+AD90*0.6) -> 0 | AJ90: =(Z90*0.4+AE90*0.6) -> 0
A91: 73 | V91: =((((E91*2.5)+(J91*10)+O91+P91)/(400))*100) -> 0 | W91: =((((F91*2.5)+(K91*10)+O91+P91)/(400))*100) -> 0 | X91: =((((G91*2.5)+(L91*10)+O91+P91)/(400))*100) -> 0 | Y91: =((((H91*2.5)+(M91*10)+O91+P91)/(400))*100) -> 0 | Z91: =((((I91*2.5)+(N91*10)+O91+P91)/(400))*100) -> 0 | AA91: =(Q91/20)*100 -> 0 | AB91: =(R91/20)*100 -> 0 | AC91: =(S91/20)*100 -> 0 | AD91: =(T91/20)*100 -> 0 | AE91: =(U91/20)*100 -> 0 | AF91: =(V91*0.4+AA91*0.6) -> 0 | AG91: =(W91*0.4+AB91*0.6) -> 0 | AH91: =(X91*0.4+AC91*0.6) -> 0 | AI91: =(Y91*0.4+AD91*0.6) -> 0 | AJ91: =(Z91*0.4+AE91*0.6) -> 0
A92: 74 | V92: =((((E92*2.5)+(J92*10)+O92+P92)/(400))*100) -> 0 | W92: =((((F92*2.5)+(K92*10)+O92+P92)/(400))*100) -> 0 | X92: =((((G92*2.5)+(L92*10)+O92+P92)/(400))*100) -> 0 | Y92: =((((H92*2.5)+(M92*10)+O92+P92)/(400))*100) -> 0 | Z92: =((((I92*2.5)+(N92*10)+O92+P92)/(400))*100) -> 0 | AA92: =(Q92/20)*100 -> 0 | AB92: =(R92/20)*100 -> 0 | AC92: =(S92/20)*100 -> 0 | AD92: =(T92/20)*100 -> 0 | AE92: =(U92/20)*100 -> 0 | AF92: =(V92*0.4+AA92*0.6) -> 0 | AG92: =(W92*0.4+AB92*0.6) -> 0 | AH92: =(X92*0.4+AC92*0.6) -> 0 | AI92: =(Y92*0.4+AD92*0.6) -> 0 | AJ92: =(Z92*0.4+AE92*0.6) -> 0
A93: 75 | V93: =((((E93*2.5)+(J93*10)+O93+P93)/(400))*100) -> 0 | W93: =((((F93*2.5)+(K93*10)+O93+P93)/(400))*100) -> 0 | X93: =((((G93*2.5)+(L93*10)+O93+P93)/(400))*100) -> 0 | Y93: =((((H93*2.5)+(M93*10)+O93+P93)/(400))*100) -> 0 | Z93: =((((I93*2.5)+(N93*10)+O93+P93)/(400))*100) -> 0 | AA93: =(Q93/20)*100 -> 0 | AB93: =(R93/20)*100 -> 0 | AC93: =(S93/20)*100 -> 0 | AD93: =(T93/20)*100 -> 0 | AE93: =(U93/20)*100 -> 0 | AF93: =(V93*0.4+AA93*0.6) -> 0 | AG93: =(W93*0.4+AB93*0.6) -> 0 | AH93: =(X93*0.4+AC93*0.6) -> 0 | AI93: =(Y93*0.4+AD93*0.6) -> 0 | AJ93: =(Z93*0.4+AE93*0.6) -> 0
A94: 76 | V94: =((((E94*2.5)+(J94*10)+O94+P94)/(400))*100) -> 0 | W94: =((((F94*2.5)+(K94*10)+O94+P94)/(400))*100) -> 0 | X94: =((((G94*2.5)+(L94*10)+O94+P94)/(400))*100) -> 0 | Y94: =((((H94*2.5)+(M94*10)+O94+P94)/(400))*100) -> 0 | Z94: =((((I94*2.5)+(N94*10)+O94+P94)/(400))*100) -> 0 | AA94: =(Q94/20)*100 -> 0 | AB94: =(R94/20)*100 -> 0 | AC94: =(S94/20)*100 -> 0 | AD94: =(T94/20)*100 -> 0 | AE94: =(U94/20)*100 -> 0 | AF94: =(V94*0.4+AA94*0.6) -> 0 | AG94: =(W94*0.4+AB94*0.6) -> 0 | AH94: =(X94*0.4+AC94*0.6) -> 0 | AI94: =(Y94*0.4+AD94*0.6) -> 0 | AJ94: =(Z94*0.4+AE94*0.6) -> 0
...

Sheet CO DIRECT ATT
A1: Sri Eshwar College of Engineering
A2: Coimbatore - 641 202
A3: =CO_ATT_INPUTS!A3 -> Department of Computer and Communication Engineering
A4: =[2]CO_ATT_INPUTS!A5 -> Regulation | D4: =CO_ATT_INPUTS!D5 -> R2019
A5: =[2]CO_ATT_INPUTS!A6 -> Program | D5: =CO_ATT_INPUTS!D6 -> BE-CCE
A6: =[2]CO_ATT_INPUTS!A7 -> Year/Semester | D6: =CO_ATT_INPUTS!D7 -> III/VI
A7: =[2]CO_ATT_INPUTS!A8 -> Course Code | D7: =CO_ATT_INPUTS!D8 -> R19IT303
A8: =[2]CO_ATT_INPUTS!A9 -> Course Name | D8: =CO_ATT_INPUTS!D9 -> CRYPTOGRAPHY AND CYBERSECURITY
A9: =[2]CO_ATT_INPUTS!A10 -> Course handling Faculty | D9: =CO_ATT_INPUTS!D10 -> R.PREETHI
A10: =[2]CO_ATT_INPUTS!A11 -> Course Coordinator | D10: =CO_ATT_INPUTS!D11 -> Dr K.Sivakumar
A11: =[2]CO_ATT_INPUTS!A12 -> Academic Year | D11: =CO_ATT_INPUTS!D12 -> 2024-25
A12: =[2]CO_ATT_INPUTS!A13 -> Batch | D12: =CO_ATT_INPUTS!D13 -> 2022-26
A13: =[2]CO_ATT_INPUTS!A14 -> Total Number of Students | D13: =CO_ATT_INPUTS!D14 -> 65
A16: =CO_ATT_INPUTS!A16 -> S. No | B16: =CO_ATT_INPUTS!B16 -> ROLL NUM | C16: =CO_ATT_INPUTS!C16 -> REGISTER NUMBER | D16: NAME OF THE STUDENT | E16: CO ASSESSMENT AND EVALUATION
E17: DIRECT ATTAINMENT = (0.4X + 0.6Y) % | J17: THROUH DIRECT ATTAINMENT INDIVIDUAL CO DIRECT ATTAINMENT >= Target % ?
E18: CO1 | F18: CO2 | G18: CO3 | H18: CO4 | I18: CO5 | J18: CO1 | K18: CO2 | L18: CO3 | M18: CO4 | N18: CO5
A19: =CO_ATT_INPUTS!A19 -> 1 | B19: =CO_ATT_INPUTS!B19 -> 22CC001 | C19: =CO_ATT_INPUTS!C19 -> 722822115001 | D19: =CO_ATT_INPUTS!D19 -> AFREED S | E19: =CO_ATT_INPUTS!AF19 -> 85.5 | F19: =CO_ATT_INPUTS!AG19 -> 76.5 | G19: =CO_ATT_INPUTS!AH19 -> 93.75 | H19: =CO_ATT_INPUTS!AI19 -> 78 | I19: =CO_ATT_INPUTS!AJ19 -> 71.75 | J19: =IF(E19>=CO_ATT_INPUTS!$C$327,CHAR(252),CHAR(251)) -> ü | K19: =IF(F19>=CO_ATT_INPUTS!$C$327,CHAR(252),CHAR(251)) -> ü | L19: =IF(G19>=CO_ATT_INPUTS!$C$327,CHAR(252),CHAR(251)) -> ü | M19: =IF(H19>=CO_ATT_INPUTS!$C$327,CHAR(252),CHAR(251)) -> ü | N19: =IF(I19>=CO_ATT_INPUTS!$C$327,CHAR(252),CHAR(251)) -> ü
A20: =CO_ATT_INPUTS!A20 -> 2 | B20: =CO_ATT_INPUTS!B20 -> 22CC002 | C20: =CO_ATT_INPUTS!C20 -> 722822115002 | D20: =CO_ATT_INPUTS!D20 -> AJAY J | E20: =CO_ATT_INPUTS!AF20 -> 70.75 | F20: =CO_ATT_INPUTS!AG20 -> 73.5 | G20: =CO_ATT_INPUTS!AH20 -> 72.75 | H20: =CO_ATT_INPUTS!AI20 -> 64 | I20: =CO_ATT_INPUTS!AJ20 -> 68.25 | J20: =IF(E20>=CO_ATT_INPUTS!$C$327,CHAR(252),CHAR(251)) -> ü | K20: =IF(F20>=CO_ATT_INPUTS!$C$327,CHAR(252),CHAR(251)) -> ü | L20: =IF(G20>=CO_ATT_INPUTS!$C$327,CHAR(252),CHAR(251)) -> ü | M20: =IF(H20>=CO_ATT_INPUTS!$C$327,CHAR(252),CHAR(251)) -> û | N20: =IF(I20>=CO_ATT_INPUTS!$C$327,CHAR(252),CHAR(251)) -> û
A21: =CO_ATT_INPUTS!A21 -> 3 | B21: =CO_ATT_INPUTS!B21 -> 22CC003 | C21: =CO_ATT_INPUTS!C21 -> 722822115003 | D21: =CO_ATT_INPUTS!D21 -> AKSHAYAN K | E21: =CO_ATT_INPUTS!AF21 -> 75.25 | F21: =CO_ATT_INPUTS!AG21 -> 71.5 | G21: =CO_ATT_INPUTS!AH21 -> 69.75 | H21: =CO_ATT_INPUTS!AI21 -> 70.5 | I21: =CO_ATT_INPUTS!AJ21 -> 66.25 | J21: =IF(E21>=CO_ATT_INPUTS!$C$327,CHAR(252),CHAR(251)) -> ü | K21: =IF(F21>=CO_ATT_INPUTS!$C$327,CHAR(252),CHAR(251)) -> ü | L21: =IF(G21>=CO_ATT_INPUTS!$C$327,CHAR(252),CHAR(251)) -> û | M21: =IF(H21>=CO_ATT_INPUTS!$C$327,CHAR(252),CHAR(251)) -> ü | N21: =IF(I21>=CO_ATT_INPUTS!$C$327,CHAR(252),CHAR(251)) -> û
A22: =CO_ATT_INPUTS!A22 -> 4 | B22: =CO_ATT_INPUTS!B22 -> 22CC004 | C22: =CO_ATT_INPUTS!C22 -> 722822115004 | D22: =CO_ATT_INPUTS!D22 -> DARSHAN R B | E22: =CO_ATT_INPUTS!AF22 -> 73.25 | F22: =CO_ATT_INPUTS!AG22 -> 66.5 | G22: =CO_ATT_INPUTS!AH22 -> 66.75 | H22: =CO_ATT_INPUTS!AI22 -> 66.75 | I22: =CO_ATT_INPUTS!AJ22 -> 67.5 | J22: =IF(E22>=CO_ATT_INPUTS!$C$327,CHAR(252),CHAR(251)) -> ü | K22: =IF(F22>=CO_ATT_INPUTS!$C$327,CHAR(252),CHAR(251)) -> û | L22: =IF(G22>=CO_ATT_INPUTS!$C$327,CHAR(252),CHAR(251)) -> û | M22: =IF(H22>=CO_ATT_INPUTS!$C$327,CHAR(252),CHAR(251)) -> û | N22: =IF(I22>=CO_ATT_INPUTS!$C$327,CHAR(252),CHAR(251)) -> û
A23: =CO_ATT_INPUTS!A23 -> 5 | B23: =CO_ATT_INPUTS!B23 -> 22CC005 | C23: =CO_ATT_INPUTS!C23 -> 722822115005 | D23: =CO_ATT_INPUTS!D23 -> DEEPAK RAJA M | E23: =CO_ATT_INPUTS!AF23 -> 82.5 | F23: =CO_ATT_INPUTS!AG23 -> 78.75 | G23: =CO_ATT_INPUTS!AH23 -> 80.75 | H23: =CO_ATT_INPUTS!AI23 -> 85 | I23: =CO_ATT_INPUTS!AJ23 -> 75.25 | J23: =IF(E23>=CO_ATT_INPUTS!$C$327,CHAR(252),CHAR(251)) -> ü | K23: =IF(F23>=CO_ATT_INPUTS!$C$327,CHAR(252),CHAR(251)) -> ü | L23: =IF(G23>=CO_ATT_INPUTS!$C$327,CHAR(252),CHAR(251)) -> ü | M23: =IF(H23>=CO_ATT_INPUTS!$C$327,CHAR(252),CHAR(251)) -> ü | N23: =IF(I23>=CO_ATT_INPUTS!$C$327,CHAR(252),CHAR(251)) -> ü
A24: =CO_ATT_INPUTS!A24 -> 6 | B24: =CO_ATT_INPUTS!B24 -> 22CC006 | C24: =CO_ATT_INPUTS!C24 -> 722822115006 | D24: =CO_ATT_INPUTS!D24 -> DHANUSHPRIYAN S | E24: =CO_ATT_INPUTS!AF24 -> 87.7 | F24: =CO_ATT_INPUTS!AG24 -> 79.45 | G24: =CO_ATT_INPUTS!AH24 -> 75.45 | H24: =CO_ATT_INPUTS!AI24 -> 75.45 | I24: =CO_ATT_INPUTS!AJ24 -> 71.7 | J24: =IF(E24>=CO_ATT_INPUTS!$C$327,CHAR(252),CHAR(251)) -> ü | K24: =IF(F24>=CO_ATT_INPUTS!$C$327,CHAR(252),CHAR(251)) -> ü | L24: =IF(G24>=CO_ATT_INPUTS!$C$327,CHAR(252),CHAR(251)) -> ü | M24: =IF(H24>=CO_ATT_INPUTS!$C$327,CHAR(252),CHAR(251)) -> ü | N24: =IF(I24>=CO_ATT_INPUTS!$C$327,CHAR(252),CHAR(251)) -> ü
A25: =CO_ATT_INPUTS!A25 -> 7 | B25: =CO_ATT_INPUTS!B25 -> 22CC007 | C25: =CO_ATT_INPUTS!C25 -> 722822115007 | D25: =CO_ATT_INPUTS!D25 -> DHARSHINI K | E25: =CO_ATT_INPUTS!AF25 -> 89.65 | F25: =CO_ATT_INPUTS!AG25 -> 88.65 | G25: =CO_ATT_INPUTS!AH25 -> 82.9 | H25: =CO_ATT_INPUTS!AI25 -> 81.65 | I25: =CO_ATT_INPUTS!AJ25 -> 77.15 | J25: =IF(E25>=CO_ATT_INPUTS!$C$327,CHAR(252),CHAR(251)) -> ü | K25: =IF(F25>=CO_ATT_INPUTS!$C$327,CHAR(252),CHAR(251)) -> ü | L25: =IF(G25>=CO_ATT_INPUTS!$C$327,CHAR(252),CHAR(251)) -> ü | M25: =IF(H25>=CO_ATT_INPUTS!$C$327,CHAR(252),CHAR(251)) -> ü | N25: =IF(I25>=CO_ATT_INPUTS!$C$327,CHAR(252),CHAR(251)) -> ü
A26: =CO_ATT_INPUTS!A26 -> 8 | B26: =CO_ATT_INPUTS!B26 -> 22CC008 | C26: =CO_ATT_INPUTS!C26 -> 722822115008 | D26: =CO_ATT_INPUTS!D26 -> DHEVADHARSHINI M | E26: =CO_ATT_INPUTS!AF26 -> 87.85 | F26: =CO_ATT_INPUTS!AG26 -> 84.35 | G26: =CO_ATT_INPUTS!AH26 -> 85.35 | H26: =CO_ATT_INPUTS!AI26 -> 76.6 | I26: =CO_ATT_INPUTS!AJ26 -> 77.85 | J26: =IF(E26>=CO_ATT_INPUTS!$C$327,CHAR(252),CHAR(251)) -> ü | K26: =IF(F26>=CO_ATT_INPUTS!$C$327,CHAR(252),CHAR(251)) -> ü | L26: =IF(G26>=CO_ATT_INPUTS!$C$327,CHAR(252),CHAR(251)) -> ü | M26: =IF(H26>=CO_ATT_INPUTS!$C$327,CHAR(252),CHAR(251)) -> ü | N26: =IF(I26>=CO_ATT_INPUTS!$C$327,CHAR(252),CHAR(251)) -> ü
A27: =CO_ATT_INPUTS!A27 -> 9 | B27: =CO_ATT_INPUTS!B27 -> 22CC009 | C27: =CO_ATT_INPUTS!C27 -> 722822115009 | D27: =CO_ATT_INPUTS!D27 -> DINESH R | E27: =CO_ATT_INPUTS!AF27 -> 71.15 | F27: =CO_ATT_INPUTS!AG27 -> 71.15 | G27: =CO_ATT_INPUTS!AH27 -> 69.9 | H27: =CO_ATT_INPUTS!AI27 -> 66.65 | I27: =CO_ATT_INPUTS!AJ27 -> 71.9 | J27: =IF(E27>=CO_ATT_INPUTS!$C$327,CHAR(252),CHAR(251)) -> ü | K27: =IF(F27>=CO_ATT_INPUTS!$C$327,CHAR(252),CHAR(251)) -> ü | L27: =IF(G27>=CO_ATT_INPUTS!$C$327,CHAR(252),CHAR(251)) -> û | M27: =IF(H27>=CO_ATT_INPUTS!$C$327,CHAR(252),CHAR(251)) -> û | N27: =IF(I27>=CO_ATT_INPUTS!$C$327,CHAR(252),CHAR(251)) -> ü
A28: =CO_ATT_INPUTS!A28 -> 10 | B28: =CO_ATT_INPUTS!B28 -> 22CC010 | C28: =CO_ATT_INPUTS!C28 -> 722822115010 | D28: =CO_ATT_INPUTS!D28 -> ELANGO T | E28: =CO_ATT_INPUTS!AF28 -> 86.95 | F28: =CO_ATT_INPUTS!AG28 -> 88.95 | G28: =CO_ATT_INPUTS!AH28 -> 83.2 | H28: =CO_ATT_INPUTS!AI28 -> 87.45 | I28: =CO_ATT_INPUTS!AJ28 -> 86.95 | J28: =IF(E28>=CO_ATT_INPUTS!$C$327,CHAR(252),CHAR(251)) -> ü | K28: =IF(F28>=CO_ATT_INPUTS!$C$327,CHAR(252),CHAR(251)) -> ü | L28: =IF(G28>=CO_ATT_INPUTS!$C$327,CHAR(252),CHAR(251)) -> ü | M28: =IF(H28>=CO_ATT_INPUTS!$C$327,CHAR(252),CHAR(251)) -> ü | N28: =IF(I28>=CO_ATT_INPUTS!$C$327,CHAR(252),CHAR(251)) -> ü
A29: =CO_ATT_INPUTS!A29 -> 11 | B29: =CO_ATT_INPUTS!B29 -> 22CC011 | C29: =CO_ATT_INPUTS!C29 -> 722822115011 | D29: =CO_ATT_INPUTS!D29 -> GAYATHIRI K | E29: =CO_ATT_INPUTS!AF29 -> 84 | F29: =CO_ATT_INPUTS!AG29 -> 83.75 | G29: =CO_ATT_INPUTS!AH29 -> 82.75 | H29: =CO_ATT_INPUTS!AI29 -> 84.25 | I29: =CO_ATT_INPUTS!AJ29 -> 84 | J29: =IF(E29>=CO_ATT_INPUTS!$C$327,CHAR(252),CHAR(251)) -> ü | K29: =IF(F29>=CO_ATT_INPUTS!$C$327,CHAR(252),CHAR(251)) -> ü | L29: =IF(G29>=CO_ATT_INPUTS!$C$327,CHAR(252),CHAR(251)) -> ü | M29: =IF(H29>=CO_ATT_INPUTS!$C$327,CHAR(252),CHAR(251)) -> ü | N29: =IF(I29>=CO_ATT_INPUTS!$C$327,CHAR(252),CHAR(251)) -> ü
A30: =CO_ATT_INPUTS!A30 -> 12 | B30: =CO_ATT_INPUTS!B30 -> 22CC012 | C30: =CO_ATT_INPUTS!C30 -> 722822115012 | D30: =CO_ATT_INPUTS!D30 -> GNANARIDDHIKA R | E30: =CO_ATT_INPUTS!AF30 -> 83.35 | F30: =CO_ATT_INPUTS!AG30 -> 68.1 | G30: =CO_ATT_INPUTS!AH30 -> 76.1 | H30: =CO_ATT_INPUTS!AI30 -> 83.1 | I30: =CO_ATT_INPUTS!AJ30 -> 74.35 | J30: =IF(E30>=CO_ATT_INPUTS!$C$327,CHAR(252),CHAR(251)) -> ü | K30: =IF(F30>=CO_ATT_INPUTS!$C$327,CHAR(252),CHAR(251)) -> û | L30: =IF(G30>=CO_ATT_INPUTS!$C$327,CHAR(252),CHAR(251)) -> ü | M30: =IF(H30>=CO_ATT_INPUTS!$C$327,CHAR(252),CHAR(251)) -> ü | N30: =IF(I30>=CO_ATT_INPUTS!$C$327,CHAR(252),CHAR(251)) -> ü
... A318: =CO_ATT_INPUTS!A318 -> 300 | B318: =CO_ATT_INPUTS!B318 -> 0 | C318: =CO_ATT_INPUTS!C318 -> 0 | D318: =CO_ATT_INPUTS!D318 -> 0 | E318: =CO_ATT_INPUTS!AF318 -> 0 | F318: =CO_ATT_INPUTS!AG318 -> 0 | G318: =CO_ATT_INPUTS!AH318 -> 0 | H318: =CO_ATT_INPUTS!AI318 -> 0 | I318: =CO_ATT_INPUTS!AJ318 -> 0 | J318: =IF(E318>=CO_ATT_INPUTS!$C$327,CHAR(252),CHAR(251)) -> û | K318: =IF(F318>=CO_ATT_INPUTS!$C$327,CHAR(252),CHAR(251)) -> û | L318: =IF(G318>=CO_ATT_INPUTS!$C$327,CHAR(252),CHAR(251)) -> û | M318: =IF(H318>=CO_ATT_INPUTS!$C$327,CHAR(252),CHAR(251)) -> û | N318: =IF(I318>=CO_ATT_INPUTS!$C$327,CHAR(252),CHAR(251)) -> û
A320: CO DIRECT ATTAINMENT | E320: CO1 | F320: CO2 | G320: CO3 | H320: CO4 | I320: CO5
A322: Total Number of Students securing Target % and above in Direct Assessment | E322: =COUNTIF(E19:E318,">="&CO_ATT_INPUTS!$D323) -> 62 | F322: =COUNTIF(F19:F318,">="&CO_ATT_INPUTS!$D323) -> 54 | G322: =COUNTIF(G19:G318,">="&CO_ATT_INPUTS!$D323) -> 46 | H322: =COUNTIF(H19:H318,">="&CO_ATT_INPUTS!$D323) -> 54 | I322: =COUNTIF(I19:I318,">="&CO_ATT_INPUTS!$D323) -> 47
A323: =#REF! -> #REF! | E323: =(E322/$D$13)*100 -> 95.384615 | F323: =(F322/$D$13)*100 -> 83.076923 | G323: =(G322/$D$13)*100 -> 70.769231 | H323: =(H322/$D$13)*100 -> 83.076923 | I323: =(I322/$D$13)*100 -> 72.307692
A324: Direct Attainment Level as per the Description | E324: =IF(E323>=CO_ATT_INPUTS!$B323,"3",IF(E323<CO_ATT_INPUTS!$B325,"1",IF(AND(E323>=CO_ATT_INPUTS!$B325,E323<CO_ATT_INPUTS!$B323),"2"))) -> 3 | F324: =IF(F323>=CO_ATT_INPUTS!$B323,"3",IF(F323<CO_ATT_INPUTS!$B325,"1",IF(AND(F323>=CO_ATT_INPUTS!$B325,F323<CO_ATT_INPUTS!$B323),"2"))) -> 3 | G324: =IF(G323>=CO_ATT_INPUTS!$B323,"3",IF(G323<CO_ATT_INPUTS!$B325,"1",IF(AND(G323>=CO_ATT_INPUTS!$B325,G323<CO_ATT_INPUTS!$B323),"2"))) -> 3 | H324: =IF(H323>=CO_ATT_INPUTS!$B323,"3",IF(H323<CO_ATT_INPUTS!$B325,"1",IF(AND(H323>=CO_ATT_INPUTS!$B325,H323<CO_ATT_INPUTS!$B323),"2"))) -> 3 | I324: =IF(I323>=CO_ATT_INPUTS!$B323,"3",IF(I323<CO_ATT_INPUTS!$B325,"1",IF(AND(I323>=CO_ATT_INPUTS!$B325,I323<CO_ATT_INPUTS!$B323),"2"))) -> 3

Sheet CO INDIRECT ATT
A1: Sri Eshwar College of Engineering
A2: Coimbatore - 641 202
A3: =CO_ATT_INPUTS!A3 -> Department of Computer and Communication Engineering
A4: =CO_ATT_INPUTS!A5 -> Regulation | D4: =CO_ATT_INPUTS!D5 -> R2019
A5: =CO_ATT_INPUTS!A6 -> Program | D5: =CO_ATT_INPUTS!D6 -> BE-CCE
A6: =CO_ATT_INPUTS!A7 -> Year/Semester | D6: =CO_ATT_INPUTS!D7 -> III/VI
A7: =CO_ATT_INPUTS!A8 -> Course Code | D7: =CO_ATT_INPUTS!D8 -> R19IT303
A8: =CO_ATT_INPUTS!A9 -> Course Name | D8: =CO_ATT_INPUTS!D9 -> CRYPTOGRAPHY AND CYBERSECURITY
A9: =CO_ATT_INPUTS!A10 -> Course handling Faculty | D9: =CO_ATT_INPUTS!D10 -> R.PREETHI
A10: =CO_ATT_INPUTS!A11 -> Course Coordinator | D10: =CO_ATT_INPUTS!D11 -> Dr K.Sivakumar
A11: =CO_ATT_INPUTS!A12 -> Academic Year | D11: =CO_ATT_INPUTS!D12 -> 2024-25
A12: =CO_ATT_INPUTS!A13 -> Batch | D12: =CO_ATT_INPUTS!D13 -> 2022-26
A13: =CO_ATT_INPUTS!A14 -> Total Number of Students | D13: =CO_ATT_INPUTS!D14 -> 65
A15: =CO_ATT_INPUTS!A16 -> S. No | B15: =CO_ATT_INPUTS!B16 -> ROLL NUM | C15: =CO_ATT_INPUTS!C16 -> REGISTER NUMBER | D15: =CO_ATT_INPUTS!D16 -> NAME OF THE STUDENT | E15: COURSE END SURVEY
E16: CO1 | F16: CO2 | G16: CO3 | H16: CO4 | I16: CO5
A17: =CO_ATT_INPUTS!A19 -> 1 | B17: =CO_ATT_INPUTS!B19 -> 22CC001 | C17: =CO_ATT_INPUTS!C19 -> 722822115001 | D17: =CO_ATT_INPUTS!D19 -> AFREED S | E17: 5 | F17: 5 | G17: 5 | H17: 5 | I17: 5
A18: =CO_ATT_INPUTS!A20 -> 2 | B18: =CO_ATT_INPUTS!B20 -> 22CC002 | C18: =CO_ATT_INPUTS!C20 -> 722822115002 | D18: =CO_ATT_INPUTS!D20 -> AJAY J | E18: 4 | F18: 4 | G18: 4 | H18: 4 | I18: 3
A19: =CO_ATT_INPUTS!A21 -> 3 | B19: =CO_ATT_INPUTS!B21 -> 22CC003 | C19: =CO_ATT_INPUTS!C21 -> 722822115003 | D19: =CO_ATT_INPUTS!D21 -> AKSHAYAN K | E19: 5 | F19: 5 | G19: 5 | H19: 5 | I19: 5
A20: =CO_ATT_INPUTS!A22 -> 4 | B20: =CO_ATT_INPUTS!B22 -> 22CC004 | C20: =CO_ATT_INPUTS!C22 -> 722822115004 | D20: =CO_ATT_INPUTS!D22 -> DARSHAN R B | E20: 5 | F20: 5 | G20: 5 | H20: 5 | I20: 5
A21: =CO_ATT_INPUTS!A23 -> 5 | B21: =CO_ATT_INPUTS!B23 -> 22CC005 | C21: =CO_ATT_INPUTS!C23 -> 722822115005 | D21: =CO_ATT_INPUTS!D23 -> DEEPAK RAJA M | E21: 4 | F21: 4 | G21: 4 | H21: 4 | I21: 4
A22: =CO_ATT_INPUTS!A24 -> 6 | B22: =CO_ATT_INPUTS!B24 -> 22CC006 | C22: =CO_ATT_INPUTS!C24 -> 722822115006 | D22: =CO_ATT_INPUTS!D24 -> DHANUSHPRIYAN S | E22: 5 | F22: 5 | G22: 5 | H22: 5 | I22: 5
A23: =CO_ATT_INPUTS!A25 -> 7 | B23: =CO_ATT_INPUTS!B25 -> 22CC007 | C23: =CO_ATT_INPUTS!C25 -> 722822115007 | D23: =CO_ATT_INPUTS!D25 -> DHARSHINI K | E23: 4 | F23: 4 | G23: 5 | H23: 5 | I23: 4
A24: =CO_ATT_INPUTS!A26 -> 8 | B24: =CO_ATT_INPUTS!B26 -> 22CC008 | C24: =CO_ATT_INPUTS!C26 -> 722822115008 | D24: =CO_ATT_INPUTS!D26 -> DHEVADHARSHINI M | E24: 5 | F24: 5 | G24: 5 | H24: 5 | I24: 5
A25: =CO_ATT_INPUTS!A27 -> 9 | B25: =CO_ATT_INPUTS!B27 -> 22CC009 | C25: =CO_ATT_INPUTS!C27 -> 722822115009 | D25: =CO_ATT_INPUTS!D27 -> DINESH R | E25: 5 | F25: 5 | G25: 5 | H25: 5 | I25: 5
A26: =CO_ATT_INPUTS!A28 -> 10 | B26: =CO_ATT_INPUTS!B28 -> 22CC010 | C26: =CO_ATT_INPUTS!C28 -> 722822115010 | D26: =CO_ATT_INPUTS!D28 -> ELANGO T | E26: 5 | F26: 5 | G26: 5 | H26: 5 | I26: 5
A27: =CO_ATT_INPUTS!A29 -> 11 | B27: =CO_ATT_INPUTS!B29 -> 22CC011 | C27: =CO_ATT_INPUTS!C29 -> 722822115011 | D27: =CO_ATT_INPUTS!D29 -> GAYATHIRI K | E27: 5 | F27: 5 | G27: 5 | H27: 4 | I27: 4
A28: =CO_ATT_INPUTS!A30 -> 12 | B28: =CO_ATT_INPUTS!B30 -> 22CC012 | C28: =CO_ATT_INPUTS!C30 -> 722822115012 | D28: =CO_ATT_INPUTS!D30 -> GNANARIDDHIKA R | E28: 4 | F28: 4 | G28: 4 | H28: 4 | I28: 4
... A81: =CO_ATT_INPUTS!A83 -> 65 | B81: =CO_ATT_INPUTS!B83 -> 22CC302 | C81: =CO_ATT_INPUTS!C83 -> 722822115302 | D81: =CO_ATT_INPUTS!D83 -> RAKESH M | E81: 5 | F81: 5 | G81: 5 | H81: 5 | I81: 5
A82: =CO_ATT_INPUTS!A84 -> 66 | B82: =CO_ATT_INPUTS!B84 -> 0 | C82: =CO_ATT_INPUTS!C84 -> 0 | D82: =CO_ATT_INPUTS!D84 -> 0
A83: =CO_ATT_INPUTS!A85 -> 67 | B83: =CO_ATT_INPUTS!B85 -> 0 | C83: =CO_ATT_INPUTS!C85 -> 0 | D83: =CO_ATT_INPUTS!D85 -> 0
A84: =CO_ATT_INPUTS!A86 -> 68 | B84: =CO_ATT_INPUTS!B86 -> 0 | C84: =CO_ATT_INPUTS!C86 -> 0 | D84: =CO_ATT_INPUTS!D86 -> 0
A85: =CO_ATT_INPUTS!A87 -> 69 | B85: =CO_ATT_INPUTS!B87 -> 0 | C85: =CO_ATT_INPUTS!C87 -> 0 | D85: =CO_ATT_INPUTS!D87 -> 0
A86: =CO_ATT_INPUTS!A88 -> 70 | B86: =CO_ATT_INPUTS!B88 -> 0 | C86: =CO_ATT_INPUTS!C88 -> 0 | D86: =CO_ATT_INPUTS!D88 -> 0
A87: =CO_ATT_INPUTS!A89 -> 71 | B87: =CO_ATT_INPUTS!B89 -> 0 | C87: =CO_ATT_INPUTS!C89 -> 0 | D87: =CO_ATT_INPUTS!D89 -> 0
A88: =CO_ATT_INPUTS!A90 -> 72 | B88: =CO_ATT_INPUTS!B90 -> 0 | C88: =CO_ATT_INPUTS!C90 -> 0 | D88: =CO_ATT_INPUTS!D90 -> 0
A89: =CO_ATT_INPUTS!A91 -> 73 | B89: =CO_ATT_INPUTS!B91 -> 0 | C89: =CO_ATT_INPUTS!C91 -> 0 | D89: =CO_ATT_INPUTS!D91 -> 0
A90: =CO_ATT_INPUTS!A92 -> 74 | B90: =CO_ATT_INPUTS!B92 -> 0 | C90: =CO_ATT_INPUTS!C92 -> 0 | D90: =CO_ATT_INPUTS!D92 -> 0
A91: =CO_ATT_INPUTS!A93 -> 75 | B91: =CO_ATT_INPUTS!B93 -> 0 | C91: =CO_ATT_INPUTS!C93 -> 0 | D91: =CO_ATT_INPUTS!D93 -> 0
A92: =CO_ATT_INPUTS!A94 -> 76 | B92: =CO_ATT_INPUTS!B94 -> 0 | C92: =CO_ATT_INPUTS!C94 -> 0 | D92: =CO_ATT_INPUTS!D94 -> 0
A93: =CO_ATT_INPUTS!A95 -> 77 | B93: =CO_ATT_INPUTS!B95 -> 0 | C93: =CO_ATT_INPUTS!C95 -> 0 | D93: =CO_ATT_INPUTS!D95 -> 0
...

Sheet CO ATT
A1: Sri Eshwar College of Engineering
A2: Coimbatore - 641 202
A3: =CO_ATT_INPUTS!A3 -> Department of Computer and Communication Engineering
A4: ='CO INDIRECT ATT'!A4:D4 -> Regulation | E4: ='CO INDIRECT ATT'!D4 -> R2019
A5: ='CO INDIRECT ATT'!A5:C5 -> Program | E5: ='CO INDIRECT ATT'!D5 -> BE-CCE
A6: ='CO INDIRECT ATT'!A6:C6 -> Year/Semester | E6: ='CO INDIRECT ATT'!D6 -> III/VI
A7: ='CO INDIRECT ATT'!A7:C7 -> Course Code | E7: ='CO INDIRECT ATT'!D7 -> R19IT303
A8: ='CO INDIRECT ATT'!A8:C8 -> Course Name | E8: ='CO INDIRECT ATT'!D8 -> CRYPTOGRAPHY AND CYBERSECURITY
A9: ='CO INDIRECT ATT'!A9:C9 -> Course handling Faculty | E9: ='CO INDIRECT ATT'!D9 -> R.PREETHI
A10: ='CO INDIRECT ATT'!A10:C10 -> Course Coordinator | E10: ='CO INDIRECT ATT'!D10 -> Dr K.Sivakumar
A11: ='CO INDIRECT ATT'!A11:C11 -> Academic Year | E11: ='CO INDIRECT ATT'!D11 -> 2024-25
A12: ='CO INDIRECT ATT'!A12:C12 -> Batch | E12: ='CO INDIRECT ATT'!D12 -> 2022-26
A13: ='CO INDIRECT ATT'!A13:C13 -> Total Number of Students | E13: ='CO INDIRECT ATT'!D13 -> 65
A14: CO ATTAINMENT
A15: CO ATTAINMENT | E15: CO1 | G15: CO2 | I15: CO3 | K15: CO4 | M15: CO5
A16: CO DIRECT ATTAINMENT | E16: ='CO DIRECT ATT'!E324 -> 3 | G16: ='CO DIRECT ATT'!F324 -> 3 | I16: ='CO DIRECT ATT'!G324 -> 3 | K16: ='CO DIRECT ATT'!H324 -> 3 | M16: ='CO DIRECT ATT'!I324 -> 3
A17: CO INDIRECT ATTAINMENT | E17: ='CO INDIRECT ATT'!E326 -> 3 | G17: ='CO INDIRECT ATT'!F326 -> 3 | I17: ='CO INDIRECT ATT'!G326 -> 3 | K17: ='CO INDIRECT ATT'!H326 -> 3 | M17: ='CO INDIRECT ATT'!I326 -> 3
A18: 80% OF DIRECT ATTAINMENT (A) | E18: =(E16*0.8) -> 2.4 | G18: =(G16*0.8) -> 2.4 | I18: =(I16*0.8) -> 2.4 | K18: =(K16*0.8) -> 2.4 | M18: =(M16*0.8) -> 2.4
A19: 20% OF INDIRECT ATTAINMENT (B) | E19: =(E17*0.2) -> 0.6 | G19: =(G17*0.2) -> 0.6 | I19: =(I17*0.2) -> 0.6 | K19: =(K17*0.2) -> 0.6 | M19: =(M17*0.2) -> 0.6
A20: OVERALL CO ATTAINMENT (A+B) | E20: =E18+E19 -> 3 | G20: =G18+G19 -> 3 | I20: =I18+I19 -> 3 | K20: =K18+K19 -> 3 | M20: =M18+M19 -> 3
A21: CO TARGET VALUE | E21: =CO_ATT_INPUTS!$D327 -> 2.1 | G21: =CO_ATT_INPUTS!$D327 -> 2.1 | I21: =CO_ATT_INPUTS!$D327 -> 2.1 | K21: =CO_ATT_INPUTS!$D327 -> 2.1 | M21: =CO_ATT_INPUTS!$D327 -> 2.1
A22: CO ATTAINMENT STATUS | E22: =IF(E20>=E21,"ATTAINED","NOT ATTAINED") -> ATTAINED | G22: =IF(G20>=G21,"ATTAINED","NOT ATTAINED") -> ATTAINED | I22: =IF(I20>=I21,"ATTAINED","NOT ATTAINED") -> ATTAINED | K22: =IF(K20>=K21,"ATTAINED","NOT ATTAINED") -> ATTAINED | M22: =IF(M20>=M21,"ATTAINED","NOT ATTAINED") -> ATTAINED
A23: CO-PO/PSO MAPPING
A24: CO/PO-PSO | B24: PO1 | C24: PO2 | D24: PO3 | E24: PO4 | F24: PO5 | G24: PO6 | H24: PO7 | I24: PO8 | J24: PO9 | K24: PO10 | L24: PO11 | M24: PO12 | N24: PSO1 | O24: PSO2
A25: CO1 | B25: ='CO_PO MAPPING_PRINT'!B42 -> 3 | C25: ='CO_PO MAPPING_PRINT'!C42 -> 2 | D25: ='CO_PO MAPPING_PRINT'!D42 -> - | E25: ='CO_PO MAPPING_PRINT'!E42 -> - | F25: ='CO_PO MAPPING_PRINT'!F42 -> - | G25: ='CO_PO MAPPING_PRINT'!G42 -> - | H25: ='CO_PO MAPPING_PRINT'!H42 -> - | I25: ='CO_PO MAPPING_PRINT'!I42 -> - | ... O25: ='CO_PO MAPPING_PRINT'!O42 -> 1
A26: CO2 | B26: ='CO_PO MAPPING_PRINT'!B43 -> 3 | C26: ='CO_PO MAPPING_PRINT'!C43 -> 2 | D26: ='CO_PO MAPPING_PRINT'!D43 -> 1 | E26: ='CO_PO MAPPING_PRINT'!E43 -> - | F26: ='CO_PO MAPPING_PRINT'!F43 -> - | G26: ='CO_PO MAPPING_PRINT'!G43 -> - | H26: ='CO_PO MAPPING_PRINT'!H43 -> - | I26: ='CO_PO MAPPING_PRINT'!I43 -> - | ... O26: ='CO_PO MAPPING_PRINT'!O43 -> 1
A27: CO3 | B27: ='CO_PO MAPPING_PRINT'!B44 -> 3 | C27: ='CO_PO MAPPING_PRINT'!C44 -> - | D27: ='CO_PO MAPPING_PRINT'!D44 -> 2 | E27: ='CO_PO MAPPING_PRINT'!E44 -> - | F27: ='CO_PO MAPPING_PRINT'!F44 -> - | G27: ='CO_PO MAPPING_PRINT'!G44 -> - | H27: ='CO_PO MAPPING_PRINT'!H44 -> - | I27: ='CO_PO MAPPING_PRINT'!I44 -> - | ... O27: ='CO_PO MAPPING_PRINT'!O44 -> 1
A28: CO4 | B28: ='CO_PO MAPPING_PRINT'!B45 -> - | C28: ='CO_PO MAPPING_PRINT'!C45 -> 3 | D28: ='CO_PO MAPPING_PRINT'!D45 -> - | E28: ='CO_PO MAPPING_PRINT'!E45 -> 1 | F28: ='CO_PO MAPPING_PRINT'!F45 -> - | G28: ='CO_PO MAPPING_PRINT'!G45 -> - | H28: ='CO_PO MAPPING_PRINT'!H45 -> - | I28: ='CO_PO MAPPING_PRINT'!I45 -> - | ... O28: ='CO_PO MAPPING_PRINT'!O45 -> -
A29: CO5 | B29: ='CO_PO MAPPING_PRINT'!B46 -> - | C29: ='CO_PO MAPPING_PRINT'!C46 -> 3 | D29: ='CO_PO MAPPING_PRINT'!D46 -> 1 | E29: ='CO_PO MAPPING_PRINT'!E46 -> 1 | F29: ='CO_PO MAPPING_PRINT'!F46 -> - | G29: ='CO_PO MAPPING_PRINT'!G46 -> - | H29: ='CO_PO MAPPING_PRINT'!H46 -> - | I29: ='CO_PO MAPPING_PRINT'!I46 -> - | ... O29: ='CO_PO MAPPING_PRINT'!O46 -> -
A30: AVG | B30: ='CO_PO MAPPING_PRINT'!B47 -> 3 | C30: ='CO_PO MAPPING_PRINT'!C47 -> 2.5 | D30: ='CO_PO MAPPING_PRINT'!D47 -> 1.3333333 | E30: ='CO_PO MAPPING_PRINT'!E47 -> 1 | F30: ='CO_PO MAPPING_PRINT'!F47 -> - | G30: ='CO_PO MAPPING_PRINT'!G47 -> - | H30: ='CO_PO MAPPING_PRINT'!H47 -> - | I30: ='CO_PO MAPPING_PRINT'!I47 -> - | ... O30: ='CO_PO MAPPING_PRINT'!O47 -> 1
A31: COURSE TO PO/PSO MAPPING
A32: PO/PSO | B32: PO1 | C32: PO2 | D32: PO3 | E32: PO4 | F32: PO5 | G32: PO6 | H32: PO7 | I32: PO8 | J32: PO9 | K32: PO10 | L32: PO11 | M32: PO12 | N32: PSO1 | O32: PSO2
A33: AVG | B33: =B30 -> 3 | C33: =C30 -> 2.5 | D33: =D30 -> 1.3333333 | E33: =E30 -> 1 | F33: =F30 -> - | G33: =G30 -> - | H33: 2 | I33: =I30 -> - | J33: =J30 -> - | K33: =K30 -> - | L33: =L30 -> - | M33: =M30 -> 1 | N33: =N30 -> 1 | O33: =O30 -> 1
B35: =COUNTIF(B42:B46, "=-") -> 2 | C35: =COUNTIF(C42:C46, "=-") -> 1 | D35: =COUNTIF(D42:D46, "=-") -> 2 | E35: =COUNTIF(E42:E46, "=-") -> 3 | F35: =COUNTIF(F42:F46, "=-") -> 5 | G35: =COUNTIF(G42:G46, "=-") -> 5 | H35: =COUNTIF(H42:H46, "=-") -> 5 | I35: =COUNTIF(I42:I46, "=-") -> 5 | ... O35: =COUNTIF(O42:O46, "=-") -> 2
B36: =5-B35 -> 3 | C36: =5-C35 -> 4 | D36: =5-D35 -> 3 | E36: =5-E35 -> 2 | F36: =5-F35 -> 0 | G36: =5-G35 -> 0 | H36: =5-H35 -> 0 | I36: =5-I35 -> 0 | ... O36: =5-O35 -> 3
B37: =SUM(B42:B46) -> 9 | C37: =SUM(C42:C46) -> 10 | D37: =SUM(D42:D46) -> 4 | E37: =SUM(E42:E46) -> 2 | F37: =SUM(F42:F46) -> 0 | G37: =SUM(G42:G46) -> 0 | H37: =SUM(H42:H46) -> 0 | I37: =SUM(I42:I46) -> 0 | ... O37: =SUM(O42:O46) -> 3
B38: =IF(B36=0,"-",B37/B36) -> 3 | C38: =IF(C36=0,"-",C37/C36) -> 2.5 | D38: =IF(D36=0,"-",D37/D36) -> 1.3333333 | E38: =IF(E36=0,"-",E37/E36) -> 1 | F38: =IF(F36=0,"-",F37/F36) -> - | G38: =IF(G36=0,"-",G37/G36) -> - | H38: =IF(H36=0,"-",H37/H36) -> - | I38: =IF(I36=0,"-",I37/I36) -> - | ... O38: =IF(O36=0,"-",O37/O36) -> 1
A40: PO/PSO ATTAINMENT THROUGH COURSE
A41: CO/PO-PSO | B41: PO1 | C41: PO2 | D41: PO3 | E41: PO4 | F41: PO5 | G41: PO6 | H41: PO7 | I41: PO8 | J41: PO9 | K41: PO10 | L41: PO11 | M41: PO12 | N41: PSO1 | O41: PSO2
A42: CO1 | B42: =IF(B25="-","-", B25*$E$20/3) -> 3 | C42: =IF(C25="-","-", C25*$E$20/3) -> 2 | D42: =IF(D25="-","-", D25*$E$20/3) -> - | E42: =IF(E25="-","-", E25*$E$20/3) -> - | F42: =IF(F25="-","-", F25*$E$20/3) -> - | G42: =IF(G25="-","-", G25*$E$20/3) -> - | H42: =IF(H25="-","-", H25*$E$20/3) -> - | I42: =IF(I25="-","-", I25*$E$20/3) -> - | ... O42: =IF(O25="-","-", O25*$E$20/3) -> 1
...

Sheet FOR SESSION PURPOSE
A1: Sri Eshwar College of Engineering
A2: Coimbatore - 641 202
A3: =CO_ATT_INPUTS!A3 -> Department of Computer and Communication Engineering
A4: Academic Year/Batch | E4: : | F4: =CO_ATT_INPUTS!F5 -> 0
A5: Program | E5: : | F5: =CO_ATT_INPUTS!F6 -> 0
A6: Semester | E6: : | F6: =CO_ATT_INPUTS!F7 -> 0
A7: Course code and Name: | E7: : | F7: =CO_ATT_INPUTS!F8 -> 0
A8: Course Handling Faculty | E8: : | F8: =CO_ATT_INPUTS!F9 -> 0
A9: Name of the course coordinator | E9: : | F9: =CO_ATT_INPUTS!F10 -> 0
A10: Total number of Students | E10: : | F10: =CO_ATT_INPUTS!F14 -> 0
E14: CIA | J14: ASSIGNMENT
A15: =CO_ATT_INPUTS!A16 -> S. No | B15: =CO_ATT_INPUTS!B16 -> ROLL NUM | C15: =CO_ATT_INPUTS!C16 -> REGISTER NUMBER | D15: =CO_ATT_INPUTS!#REF! -> #REF! | E15: CO1 (40) | F15: CO2 (40) | G15: CO3 (40) | H15: CO4 (40) | I15: CO5 (40) | J15: CO1 (10) | K15: CO2 (10) | L15: CO3 (10) | M15: CO4 (10) | N15: CO5 (10) | O15: Presentation (100) | P15: Quiz (100) | Q15: (Only through internal assessment) CO value in % = total numerator / total denominator (x) | V15: (Only through external assessment) End semester exam (marks % equivalent of grade or individual CO values in %) (y) | W15: Final CO attainment value in % = 0.4 x+ 0.6 y (Assuming weightage for internal assessment as 40% and external assessment as 60%)
W16: CO1 | Z16: CO2 | AB16: CO3 | AD16: CO4 | AF16: CO5
Q17: CO1 | R17: CO2 | S17: CO3 | T17: CO4 | U17: CO5 | W17: 0.4X | X17: 0.6Y | Y17: Total | Z17: 0.4X | AA17: Total | AB17: 0.4X | AC17: Total | AD17: 0.4X | AE17: Total | AF17: 0.4X | AG17: Total
A18: =CO_ATT_INPUTS!A19 -> 1 | B18: =CO_ATT_INPUTS!B19 -> 22CC001 | C18: =CO_ATT_INPUTS!C19 -> 722822115001 | D18: =CO_ATT_INPUTS!#REF! -> #REF! | E18: =CO_ATT_INPUTS!E19 -> 26 | F18: =CO_ATT_INPUTS!F19 -> 26 | G18: =CO_ATT_INPUTS!G19 -> 23 | H18: =CO_ATT_INPUTS!H19 -> 32 | I18: =CO_ATT_INPUTS!I19 -> 31 | J18: =CO_ATT_INPUTS!J19 -> 9 | K18: =CO_ATT_INPUTS!K19 -> 9 | L18: =CO_ATT_INPUTS!L19 -> 9 | ... P18: =CO_ATT_INPUTS!P19 -> 100 | Q18: =#REF! -> #REF! | R18: =#REF! -> #REF! | S18: =#REF! -> #REF! | T18: =#REF! -> #REF! | U18: =#REF! -> #REF! | V18: =#REF! -> #REF! | W18: =Q18*0.4 -> #REF! | X18: =V18*0.6 -> #REF! | Y18: =W18+X18 -> #REF! | Z18: =0.4*R18 -> #REF! | AA18: =Z18+X18 -> #REF! | AB18: =0.4*S18 -> #REF! | AC18: =AB18+X18 -> #REF! | AD18: =0.4*T18 -> #REF! | AE18: =AD18+X18 -> #REF! | AF18: =0.4*U18 -> #REF! | AG18: =AF18+X18 -> #REF! | AH18: =B18 -> 22CC001
